{"version":3,"sources":["Error handling.js"],"names":[],"mappings":";;eAIU;;;;;;AAAV,SAAU,GAAV;;;;;;;2BAEc;;;;;;;;;;AAEN,4BAAQ,GAAR,CAAY,2BAAZ;;;;2BAEE;;;0BACA;;;;;;;;CAPV;;AAUA,IAAI,WAAW,KAAX;AACJ,QAAQ,GAAR,CAAY,SAAS,IAAT,EAAZ;AACA,IAAG;AACC,aAAS,KAAT,CAAe,aAAf,EADD;AAEC,YAAQ,GAAR,CAAY,SAAS,IAAT,EAAZ,EAFD;CAAH,CAGC,OAAM,KAAN,EAAY;AACT,YAAQ,GAAR,CAAY,KAAZ,EADS;CAAZ;AAGD,QAAQ,GAAR,CAAY,SAAS,IAAT,EAAZ","file":"Error handling-compiled.js","sourcesContent":["/**\r\n * Created by JCLG on 3/29/2016.\r\n */\r\n\r\nfunction *foo(){\r\n    try{\r\n        yield 1;\r\n    }catch(error){\r\n        console.log('inside foo '+error);\r\n    }\r\n    yield 2;\r\n    throw 'This is an error';\r\n}\r\n\r\nvar iterator = foo();\r\nconsole.log(iterator.next());\r\ntry{\r\n    iterator.throw('Hello Error');\r\n    console.log(iterator.next());\r\n}catch(error){\r\n    console.log(error);\r\n}\r\nconsole.log(iterator.next());\r\n"]}